TypeError: agg function failed [how->mean,dtype->object]
Traceback:
File "/home/runner/workspace/.pythonlibs/lib/python3.11/site-packages/streamlit/runtime/scriptrunner/exec_code.py", line 121, in exec_func_with_error_handling
    result = func()
             ^^^^^^
File "/home/runner/workspace/.pythonlibs/lib/python3.11/site-packages/streamlit/runtime/scriptrunner/script_runner.py", line 591, in code_to_exec
    exec(code, module.__dict__)
File "/home/runner/workspace/main.py", line 136, in <module>
    main()
File "/home/runner/workspace/main.py", line 125, in main
    team_data = dm.get_team_performance()
                ^^^^^^^^^^^^^^^^^^^^^^^^^
File "/home/runner/workspace/data_manager.py", line 76, in get_team_performance
    return matches_df.groupby('Date').mean()[['Technical', 'Tactical', 'Physical', 'Mental']]
           ^^^^^^^^^^^^^^^^^^^^^^^^^^^^^^^^^
File "/home/runner/workspace/.pythonlibs/lib/python3.11/site-packages/pandas/core/groupby/groupby.py", line 2452, in mean
    result = self._cython_agg_general(
             ^^^^^^^^^^^^^^^^^^^^^^^^^
File "/home/runner/workspace/.pythonlibs/lib/python3.11/site-packages/pandas/core/groupby/groupby.py", line 1998, in _cython_agg_general
    new_mgr = data.grouped_reduce(array_func)
              ^^^^^^^^^^^^^^^^^^^^^^^^^^^^^^^
File "/home/runner/workspace/.pythonlibs/lib/python3.11/site-packages/pandas/core/internals/managers.py", line 1469, in grouped_reduce
    applied = sb.apply(func)
              ^^^^^^^^^^^^^^
File "/home/runner/workspace/.pythonlibs/lib/python3.11/site-packages/pandas/core/internals/blocks.py", line 393, in apply
    result = func(self.values, **kwargs)
             ^^^^^^^^^^^^^^^^^^^^^^^^^^^
File "/home/runner/workspace/.pythonlibs/lib/python3.11/site-packages/pandas/core/groupby/groupby.py", line 1995, in array_func
    result = self._agg_py_fallback(how, values, ndim=data.ndim, alt=alt)
             ^^^^^^^^^^^^^^^^^^^^^^^^^^^^^^^^^^^^^^^^^^^^^^^^^^^^^^^^^^^
File "/home/runner/workspace/.pythonlibs/lib/python3.11/site-packages/pandas/core/groupby/groupby.py", line 1946, in _agg_py_fallback
    raise type(err)(msg) from err